Workbook

Sheet Projektübersicht
A1: Kunde
A2: Kurzbezeichnung des Vorhabens | D2: # | E2: Vorname | F2: Nachname | G2: Projektbeteiligt von | H2: Projektbeteiligt bis
A3: Projektkürzel intern | D3: 1
A4: Vorhabens-ID | D4: =IF(E4="","",D3+1)
A5: Projektstart | D5: =IF(E5="","",D4+1)
A6: Projektende | D6: =IF(E6="","",D5+1)
A7: Förderprogramm | D7: =IF(E7="","",D6+1)
D8: =IF(E8="","",D7+1)
D9: =IF(E9="","",D8+1)
A10: Legende | D10: =IF(E10="","",D9+1)
D11: =IF(E11="","",D10+1)
B12: Bitte ausfüllen | D12: =IF(E12="","",D11+1)
D13: =IF(E13="","",D12+1)
D14: =IF(E14="","",D13+1)
D15: =IF(E15="","",D14+1)
D16: =IF(E16="","",D15+1)
D17: =IF(E17="","",D16+1)
D18: =IF(E18="","",D17+1)
D19: =IF(E19="","",D18+1)
D20: =IF(E20="","",D19+1)
D21: =IF(E21="","",D20+1)
D22: =IF(E22="","",D21+1)
D23: =IF(E23="","",D22+1)
D24: =IF(E24="","",D23+1)
... D31: =IF(E31="","",D30+1)
D32: =IF(E32="","",D31+1) | G32: =IF($B32="","",#REF!) | H32: =IF($B32="","",#REF!)
D33: =IF(E33="","",#REF!+1)

Sheet IST Gehälter
G1: Monatliches IST Bruttogehalt | T1: Monatliche Kosten zur Zukunftssicherung (i.d.R. Arbeitgeberanteil der Sozialversicherung (RV-, AV-, KV-, PV-Beitrag)) | AG1: RV-Arbeitgeberbeitrag | AT1: AV-Arbeitgeberbeitrag | BG1: KV-Arbeitgeberbeitrag | BT1: PV-Arbeitgeberbeitrag | CG1: Sonstige Kosten zur Zukunftssicherung
A2: # | B2: Vorname | C2: Nachname | E2: Beschäftigt auf Projekt seit | F2: Beschäftigt auf Projekt bis | G2: =YEAR(Projektübersicht!B5) -> 1900 | T2: =G2 -> 1900 | AG2: =G2 -> 1900 | AT2: =G2 -> 1900 | BG2: =G2 -> 1900 | BT2: =G2 -> 1900 | CG2: =G2 -> 1900
A3: # | D3: Kontrolle | G3: Jan | H3: Feb | I3: Mar | J3: Apr | K3: Mai | L3: Jun | M3: Jul | N3: Aug | O3: Sep | P3: Okt | Q3: Nov | R3: Dez | T3: Jan | U3: Feb | V3: Mar | W3: Apr | X3: Mai | Y3: Jun | Z3: Jul | AA3: Aug | AB3: Sep | AC3: Okt | AD3: Nov | AE3: Dez | AG3: Jan | AH3: Feb | AI3: Mar | AJ3: Apr | AK3: Mai | AL3: Jun | AM3: Jul | AN3: Aug | AO3: Sep | AP3: Okt | AQ3: Nov | AR3: Dez | AT3: Jan | AU3: Feb | AV3: Mar | AW3: Apr | AX3: Mai | AY3: Jun | AZ3: Jul | BA3: Aug | BB3: Sep | BC3: Okt | BD3: Nov | BE3: Dez | BG3: Jan | BH3: Feb | BI3: Mar | BJ3: Apr | BK3: Mai | BL3: Jun | BM3: Jul | BN3: Aug | BO3: Sep | BP3: Okt | BQ3: Nov | BR3: Dez | BT3: Jan | BU3: Feb | BV3: Mar | BW3: Apr | BX3: Mai | BY3: Jun | BZ3: Jul | CA3: Aug | CB3: Sep | CC3: Okt | CD3: Nov | CE3: Dez | CG3: Jan | CH3: Feb | CI3: Mar | CJ3: Apr | CK3: Mai | CL3: Jun | CM3: Jul | CN3: Aug | CO3: Sep | CP3: Okt | CQ3: Nov | CR3: Dez
A4: =IF(Projektübersicht!D3="","",Projektübersicht!D3) -> 1 | B4: =IF(Projektübersicht!E3="","",Projektübersicht!E3) | C4: =IF(Projektübersicht!F3="","",Projektübersicht!F3) | E4: =IF(Projektübersicht!G3="","",Projektübersicht!G3) | F4: =IF(Projektübersicht!H3="","",Projektübersicht!H3) | T4: =SUM(AG4,AT4,BG4,BT4,CG4) -> 0 | U4: =SUM(AH4,AU4,BH4,BU4,CH4) -> 0 | V4: =SUM(AI4,AV4,BI4,BV4,CI4) -> 0 | W4: =SUM(AJ4,AW4,BJ4,BW4,CJ4) -> 0 | X4: =SUM(AK4,AX4,BK4,BX4,CK4) -> 0 | Y4: =SUM(AL4,AY4,BL4,BY4,CL4) -> 0 | Z4: =SUM(AM4,AZ4,BM4,BZ4,CM4) -> 0 | AA4: =SUM(AN4,BA4,BN4,CA4,CN4) -> 0 | ... AE4: =SUM(AR4,BE4,BR4,CE4,CR4) -> 0
A5: =IF(Projektübersicht!D4="","",Projektübersicht!D4) | B5: =IF(Projektübersicht!E4="","",Projektübersicht!E4) | C5: =IF(Projektübersicht!F4="","",Projektübersicht!F4) | E5: =IF(Projektübersicht!G4="","",Projektübersicht!G4) | F5: =IF(Projektübersicht!H4="","",Projektübersicht!H4) | T5: =SUM(AG5,AT5,BG5,BT5,CG5) -> 0 | U5: =SUM(AH5,AU5,BH5,BU5,CH5) -> 0 | V5: =SUM(AI5,AV5,BI5,BV5,CI5) -> 0 | W5: =SUM(AJ5,AW5,BJ5,BW5,CJ5) -> 0 | X5: =SUM(AK5,AX5,BK5,BX5,CK5) -> 0 | Y5: =SUM(AL5,AY5,BL5,BY5,CL5) -> 0 | Z5: =SUM(AM5,AZ5,BM5,BZ5,CM5) -> 0 | AA5: =SUM(AN5,BA5,BN5,CA5,CN5) -> 0 | ... AE5: =SUM(AR5,BE5,BR5,CE5,CR5) -> 0
A6: =IF(Projektübersicht!D5="","",Projektübersicht!D5) | B6: =IF(Projektübersicht!E5="","",Projektübersicht!E5) | C6: =IF(Projektübersicht!F5="","",Projektübersicht!F5) | E6: =IF(Projektübersicht!G5="","",Projektübersicht!G5) | F6: =IF(Projektübersicht!H5="","",Projektübersicht!H5) | T6: =SUM(AG6,AT6,BG6,BT6,CG6) -> 0 | U6: =SUM(AH6,AU6,BH6,BU6,CH6) -> 0 | V6: =SUM(AI6,AV6,BI6,BV6,CI6) -> 0 | W6: =SUM(AJ6,AW6,BJ6,BW6,CJ6) -> 0 | X6: =SUM(AK6,AX6,BK6,BX6,CK6) -> 0 | Y6: =SUM(AL6,AY6,BL6,BY6,CL6) -> 0 | Z6: =SUM(AM6,AZ6,BM6,BZ6,CM6) -> 0 | AA6: =SUM(AN6,BA6,BN6,CA6,CN6) -> 0 | ... AE6: =SUM(AR6,BE6,BR6,CE6,CR6) -> 0
A7: =IF(Projektübersicht!D6="","",Projektübersicht!D6) | B7: =IF(Projektübersicht!E6="","",Projektübersicht!E6) | C7: =IF(Projektübersicht!F6="","",Projektübersicht!F6) | E7: =IF(Projektübersicht!G6="","",Projektübersicht!G6) | F7: =IF(Projektübersicht!H6="","",Projektübersicht!H6) | T7: =SUM(AG7,AT7,BG7,BT7,CG7) -> 0 | U7: =SUM(AH7,AU7,BH7,BU7,CH7) -> 0 | V7: =SUM(AI7,AV7,BI7,BV7,CI7) -> 0 | W7: =SUM(AJ7,AW7,BJ7,BW7,CJ7) -> 0 | X7: =SUM(AK7,AX7,BK7,BX7,CK7) -> 0 | Y7: =SUM(AL7,AY7,BL7,BY7,CL7) -> 0 | Z7: =SUM(AM7,AZ7,BM7,BZ7,CM7) -> 0 | AA7: =SUM(AN7,BA7,BN7,CA7,CN7) -> 0 | ... AE7: =SUM(AR7,BE7,BR7,CE7,CR7) -> 0
A8: =IF(Projektübersicht!D7="","",Projektübersicht!D7) | B8: =IF(Projektübersicht!E7="","",Projektübersicht!E7) | C8: =IF(Projektübersicht!F7="","",Projektübersicht!F7) | E8: =IF(Projektübersicht!G7="","",Projektübersicht!G7) | F8: =IF(Projektübersicht!H7="","",Projektübersicht!H7) | T8: =SUM(AG8,AT8,BG8,BT8,CG8) -> 0 | U8: =SUM(AH8,AU8,BH8,BU8,CH8) -> 0 | V8: =SUM(AI8,AV8,BI8,BV8,CI8) -> 0 | W8: =SUM(AJ8,AW8,BJ8,BW8,CJ8) -> 0 | X8: =SUM(AK8,AX8,BK8,BX8,CK8) -> 0 | Y8: =SUM(AL8,AY8,BL8,BY8,CL8) -> 0 | Z8: =SUM(AM8,AZ8,BM8,BZ8,CM8) -> 0 | AA8: =SUM(AN8,BA8,BN8,CA8,CN8) -> 0 | ... AE8: =SUM(AR8,BE8,BR8,CE8,CR8) -> 0
A9: =IF(Projektübersicht!D8="","",Projektübersicht!D8) | B9: =IF(Projektübersicht!E8="","",Projektübersicht!E8) | C9: =IF(Projektübersicht!F8="","",Projektübersicht!F8) | E9: =IF(Projektübersicht!G8="","",Projektübersicht!G8) | F9: =IF(Projektübersicht!H8="","",Projektübersicht!H8) | T9: =SUM(AG9,AT9,BG9,BT9,CG9) -> 0 | U9: =SUM(AH9,AU9,BH9,BU9,CH9) -> 0 | V9: =SUM(AI9,AV9,BI9,BV9,CI9) -> 0 | W9: =SUM(AJ9,AW9,BJ9,BW9,CJ9) -> 0 | X9: =SUM(AK9,AX9,BK9,BX9,CK9) -> 0 | Y9: =SUM(AL9,AY9,BL9,BY9,CL9) -> 0 | Z9: =SUM(AM9,AZ9,BM9,BZ9,CM9) -> 0 | AA9: =SUM(AN9,BA9,BN9,CA9,CN9) -> 0 | ... AE9: =SUM(AR9,BE9,BR9,CE9,CR9) -> 0
A10: =IF(Projektübersicht!D9="","",Projektübersicht!D9) | B10: =IF(Projektübersicht!E9="","",Projektübersicht!E9) | C10: =IF(Projektübersicht!F9="","",Projektübersicht!F9) | E10: =IF(Projektübersicht!G9="","",Projektübersicht!G9) | F10: =IF(Projektübersicht!H9="","",Projektübersicht!H9) | T10: =SUM(AG10,AT10,BG10,BT10,CG10) -> 0 | U10: =SUM(AH10,AU10,BH10,BU10,CH10) -> 0 | V10: =SUM(AI10,AV10,BI10,BV10,CI10) -> 0 | W10: =SUM(AJ10,AW10,BJ10,BW10,CJ10) -> 0 | X10: =SUM(AK10,AX10,BK10,BX10,CK10) -> 0 | Y10: =SUM(AL10,AY10,BL10,BY10,CL10) -> 0 | Z10: =SUM(AM10,AZ10,BM10,BZ10,CM10) -> 0 | AA10: =SUM(AN10,BA10,BN10,CA10,CN10) -> 0 | ... AE10: =SUM(AR10,BE10,BR10,CE10,CR10) -> 0
A11: =IF(Projektübersicht!D10="","",Projektübersicht!D10) | B11: =IF(Projektübersicht!E10="","",Projektübersicht!E10) | C11: =IF(Projektübersicht!F10="","",Projektübersicht!F10) | E11: =IF(Projektübersicht!G10="","",Projektübersicht!G10) | F11: =IF(Projektübersicht!H10="","",Projektübersicht!H10) | T11: =SUM(AG11,AT11,BG11,BT11,CG11) -> 0 | U11: =SUM(AH11,AU11,BH11,BU11,CH11) -> 0 | V11: =SUM(AI11,AV11,BI11,BV11,CI11) -> 0 | W11: =SUM(AJ11,AW11,BJ11,BW11,CJ11) -> 0 | X11: =SUM(AK11,AX11,BK11,BX11,CK11) -> 0 | Y11: =SUM(AL11,AY11,BL11,BY11,CL11) -> 0 | Z11: =SUM(AM11,AZ11,BM11,BZ11,CM11) -> 0 | AA11: =SUM(AN11,BA11,BN11,CA11,CN11) -> 0 | ... AE11: =SUM(AR11,BE11,BR11,CE11,CR11) -> 0
A12: =IF(Projektübersicht!D11="","",Projektübersicht!D11) | B12: =IF(Projektübersicht!E11="","",Projektübersicht!E11) | C12: =IF(Projektübersicht!F11="","",Projektübersicht!F11) | E12: =IF(Projektübersicht!G11="","",Projektübersicht!G11) | F12: =IF(Projektübersicht!H11="","",Projektübersicht!H11) | T12: =SUM(AG12,AT12,BG12,BT12,CG12) -> 0 | U12: =SUM(AH12,AU12,BH12,BU12,CH12) -> 0 | V12: =SUM(AI12,AV12,BI12,BV12,CI12) -> 0 | W12: =SUM(AJ12,AW12,BJ12,BW12,CJ12) -> 0 | X12: =SUM(AK12,AX12,BK12,BX12,CK12) -> 0 | Y12: =SUM(AL12,AY12,BL12,BY12,CL12) -> 0 | Z12: =SUM(AM12,AZ12,BM12,BZ12,CM12) -> 0 | AA12: =SUM(AN12,BA12,BN12,CA12,CN12) -> 0 | ... AE12: =SUM(AR12,BE12,BR12,CE12,CR12) -> 0
A13: =IF(Projektübersicht!D12="","",Projektübersicht!D12) | B13: =IF(Projektübersicht!E12="","",Projektübersicht!E12) | C13: =IF(Projektübersicht!F12="","",Projektübersicht!F12) | E13: =IF(Projektübersicht!G12="","",Projektübersicht!G12) | F13: =IF(Projektübersicht!H12="","",Projektübersicht!H12) | T13: =SUM(AG13,AT13,BG13,BT13,CG13) -> 0 | U13: =SUM(AH13,AU13,BH13,BU13,CH13) -> 0 | V13: =SUM(AI13,AV13,BI13,BV13,CI13) -> 0 | W13: =SUM(AJ13,AW13,BJ13,BW13,CJ13) -> 0 | X13: =SUM(AK13,AX13,BK13,BX13,CK13) -> 0 | Y13: =SUM(AL13,AY13,BL13,BY13,CL13) -> 0 | Z13: =SUM(AM13,AZ13,BM13,BZ13,CM13) -> 0 | AA13: =SUM(AN13,BA13,BN13,CA13,CN13) -> 0 | ... AE13: =SUM(AR13,BE13,BR13,CE13,CR13) -> 0
A14: =IF(Projektübersicht!D13="","",Projektübersicht!D13) | B14: =IF(Projektübersicht!E13="","",Projektübersicht!E13) | C14: =IF(Projektübersicht!F13="","",Projektübersicht!F13) | E14: =IF(Projektübersicht!G13="","",Projektübersicht!G13) | F14: =IF(Projektübersicht!H13="","",Projektübersicht!H13) | T14: =SUM(AG14,AT14,BG14,BT14,CG14) -> 0 | U14: =SUM(AH14,AU14,BH14,BU14,CH14) -> 0 | V14: =SUM(AI14,AV14,BI14,BV14,CI14) -> 0 | W14: =SUM(AJ14,AW14,BJ14,BW14,CJ14) -> 0 | X14: =SUM(AK14,AX14,BK14,BX14,CK14) -> 0 | Y14: =SUM(AL14,AY14,BL14,BY14,CL14) -> 0 | Z14: =SUM(AM14,AZ14,BM14,BZ14,CM14) -> 0 | AA14: =SUM(AN14,BA14,BN14,CA14,CN14) -> 0 | ... AE14: =SUM(AR14,BE14,BR14,CE14,CR14) -> 0
A15: =IF(Projektübersicht!D14="","",Projektübersicht!D14) | B15: =IF(Projektübersicht!E14="","",Projektübersicht!E14) | C15: =IF(Projektübersicht!F14="","",Projektübersicht!F14) | E15: =IF(Projektübersicht!G14="","",Projektübersicht!G14) | F15: =IF(Projektübersicht!H14="","",Projektübersicht!H14) | T15: =SUM(AG15,AT15,BG15,BT15,CG15) -> 0 | U15: =SUM(AH15,AU15,BH15,BU15,CH15) -> 0 | V15: =SUM(AI15,AV15,BI15,BV15,CI15) -> 0 | W15: =SUM(AJ15,AW15,BJ15,BW15,CJ15) -> 0 | X15: =SUM(AK15,AX15,BK15,BX15,CK15) -> 0 | Y15: =SUM(AL15,AY15,BL15,BY15,CL15) -> 0 | Z15: =SUM(AM15,AZ15,BM15,BZ15,CM15) -> 0 | AA15: =SUM(AN15,BA15,BN15,CA15,CN15) -> 0 | ... AE15: =SUM(AR15,BE15,BR15,CE15,CR15) -> 0
... A33: =IF(Projektübersicht!D32="","",Projektübersicht!D32) | B33: =IF(Projektübersicht!E32="","",Projektübersicht!E32) | C33: =IF(Projektübersicht!F32="","",Projektübersicht!F32) | E33: =IF(Projektübersicht!G32="","",Projektübersicht!G32) | F33: =IF(Projektübersicht!H32="","",Projektübersicht!H32) | T33: =SUM(AG33,AT33,BG33,BT33,CG33) -> 0 | U33: =SUM(AH33,AU33,BH33,BU33,CH33) -> 0 | V33: =SUM(AI33,AV33,BI33,BV33,CI33) -> 0 | W33: =SUM(AJ33,AW33,BJ33,BW33,CJ33) -> 0 | X33: =SUM(AK33,AX33,BK33,BX33,CK33) -> 0 | Y33: =SUM(AL33,AY33,BL33,BY33,CL33) -> 0 | Z33: =SUM(AM33,AZ33,BM33,BZ33,CM33) -> 0 | AA33: =SUM(AN33,BA33,BN33,CA33,CN33) -> 0 | ... AE33: =SUM(AR33,BE33,BR33,CE33,CR33) -> 0
A40: # | B40: Vorname | C40: Nachname | E40: Beschäftigt auf Projekt seit | F40: Beschäftigt auf Projekt bis | G40: =G2+1 -> 1901 | T40: =G40 -> 1901 | AG40: =AG2+1 -> 1901 | AT40: =AT2+1 -> 1901 | BG40: =BG2+1 -> 1901 | BT40: =BT2+1 -> 1901 | CG40: =CG2+1 -> 1901
A41: # | G41: Jan | H41: Feb | I41: Mar | J41: Apr | K41: Mai | L41: Jun | M41: Jul | N41: Aug | O41: Sep | P41: Okt | Q41: Nov | R41: Dez | T41: Jan | U41: Feb | V41: Mar | W41: Apr | X41: Mai | Y41: Jun | Z41: Jul | AA41: Aug | AB41: Sep | AC41: Okt | AD41: Nov | AE41: Dez | AG41: Jan | AH41: Feb | AI41: Mar | AJ41: Apr | AK41: Mai | AL41: Jun | AM41: Jul | AN41: Aug | AO41: Sep | AP41: Okt | AQ41: Nov | AR41: Dez | AT41: Jan | AU41: Feb | AV41: Mar | AW41: Apr | AX41: Mai | AY41: Jun | AZ41: Jul | BA41: Aug | BB41: Sep | BC41: Okt | BD41: Nov | BE41: Dez | BG41: Jan | BH41: Feb | BI41: Mar | BJ41: Apr | BK41: Mai | BL41: Jun | BM41: Jul | BN41: Aug | BO41: Sep | BP41: Okt | BQ41: Nov | BR41: Dez | BT41: Jan | BU41: Feb | BV41: Mar | BW41: Apr | BX41: Mai | BY41: Jun | BZ41: Jul | CA41: Aug | CB41: Sep | CC41: Okt | CD41: Nov | CE41: Dez | CG41: Jan | CH41: Feb | CI41: Mar | CJ41: Apr | CK41: Mai | CL41: Jun | CM41: Jul | CN41: Aug | CO41: Sep | CP41: Okt | CQ41: Nov | CR41: Dez
A42: =A4 -> 1 | B42: =B4 | C42: =C4 | E42: =E4 | F42: =F4 | T42: =SUM(AG42,AT42,BG42,BT42,CG42) -> 0 | U42: =SUM(AH42,AU42,BH42,BU42,CH42) -> 0 | V42: =SUM(AI42,AV42,BI42,BV42,CI42) -> 0 | W42: =SUM(AJ42,AW42,BJ42,BW42,CJ42) -> 0 | X42: =SUM(AK42,AX42,BK42,BX42,CK42) -> 0 | Y42: =SUM(AL42,AY42,BL42,BY42,CL42) -> 0 | Z42: =SUM(AM42,AZ42,BM42,BZ42,CM42) -> 0 | AA42: =SUM(AN42,BA42,BN42,CA42,CN42) -> 0 | ... AE42: =SUM(AR42,BE42,BR42,CE42,CR42) -> 0
A43: =A5 | B43: =B5 | C43: =C5 | E43: =E5 | F43: =F5 | T43: =SUM(AG43,AT43,BG43,BT43,CG43) -> 0 | U43: =SUM(AH43,AU43,BH43,BU43,CH43) -> 0 | V43: =SUM(AI43,AV43,BI43,BV43,CI43) -> 0 | W43: =SUM(AJ43,AW43,BJ43,BW43,CJ43) -> 0 | X43: =SUM(AK43,AX43,BK43,BX43,CK43) -> 0 | Y43: =SUM(AL43,AY43,BL43,BY43,CL43) -> 0 | Z43: =SUM(AM43,AZ43,BM43,BZ43,CM43) -> 0 | AA43: =SUM(AN43,BA43,BN43,CA43,CN43) -> 0 | ... AE43: =SUM(AR43,BE43,BR43,CE43,CR43) -> 0
A44: =A6 | B44: =B6 | C44: =C6 | E44: =E6 | F44: =F6 | T44: =SUM(AG44,AT44,BG44,BT44,CG44) -> 0 | U44: =SUM(AH44,AU44,BH44,BU44,CH44) -> 0 | V44: =SUM(AI44,AV44,BI44,BV44,CI44) -> 0 | W44: =SUM(AJ44,AW44,BJ44,BW44,CJ44) -> 0 | X44: =SUM(AK44,AX44,BK44,BX44,CK44) -> 0 | Y44: =SUM(AL44,AY44,BL44,BY44,CL44) -> 0 | Z44: =SUM(AM44,AZ44,BM44,BZ44,CM44) -> 0 | AA44: =SUM(AN44,BA44,BN44,CA44,CN44) -> 0 | ... AE44: =SUM(AR44,BE44,BR44,CE44,CR44) -> 0
A45: =A7 | B45: =B7 | C45: =C7 | E45: =E7 | F45: =F7 | T45: =SUM(AG45,AT45,BG45,BT45,CG45) -> 0 | U45: =SUM(AH45,AU45,BH45,BU45,CH45) -> 0 | V45: =SUM(AI45,AV45,BI45,BV45,CI45) -> 0 | W45: =SUM(AJ45,AW45,BJ45,BW45,CJ45) -> 0 | X45: =SUM(AK45,AX45,BK45,BX45,CK45) -> 0 | Y45: =SUM(AL45,AY45,BL45,BY45,CL45) -> 0 | Z45: =SUM(AM45,AZ45,BM45,BZ45,CM45) -> 0 | AA45: =SUM(AN45,BA45,BN45,CA45,CN45) -> 0 | ... AE45: =SUM(AR45,BE45,BR45,CE45,CR45) -> 0
A46: =A8 | B46: =B8 | C46: =C8 | E46: =E8 | F46: =F8 | T46: =SUM(AG46,AT46,BG46,BT46,CG46) -> 0 | U46: =SUM(AH46,AU46,BH46,BU46,CH46) -> 0 | V46: =SUM(AI46,AV46,BI46,BV46,CI46) -> 0 | W46: =SUM(AJ46,AW46,BJ46,BW46,CJ46) -> 0 | X46: =SUM(AK46,AX46,BK46,BX46,CK46) -> 0 | Y46: =SUM(AL46,AY46,BL46,BY46,CL46) -> 0 | Z46: =SUM(AM46,AZ46,BM46,BZ46,CM46) -> 0 | AA46: =SUM(AN46,BA46,BN46,CA46,CN46) -> 0 | ... AE46: =SUM(AR46,BE46,BR46,CE46,CR46) -> 0
A47: =A9 | B47: =B9 | C47: =C9 | E47: =E9 | F47: =F9 | T47: =SUM(AG47,AT47,BG47,BT47,CG47) -> 0 | U47: =SUM(AH47,AU47,BH47,BU47,CH47) -> 0 | V47: =SUM(AI47,AV47,BI47,BV47,CI47) -> 0 | W47: =SUM(AJ47,AW47,BJ47,BW47,CJ47) -> 0 | X47: =SUM(AK47,AX47,BK47,BX47,CK47) -> 0 | Y47: =SUM(AL47,AY47,BL47,BY47,CL47) -> 0 | Z47: =SUM(AM47,AZ47,BM47,BZ47,CM47) -> 0 | AA47: =SUM(AN47,BA47,BN47,CA47,CN47) -> 0 | ... AE47: =SUM(AR47,BE47,BR47,CE47,CR47) -> 0
A48: =A10 | B48: =B10 | C48: =C10 | E48: =E10 | F48: =F10 | T48: =SUM(AG48,AT48,BG48,BT48,CG48) -> 0 | U48: =SUM(AH48,AU48,BH48,BU48,CH48) -> 0 | V48: =SUM(AI48,AV48,BI48,BV48,CI48) -> 0 | W48: =SUM(AJ48,AW48,BJ48,BW48,CJ48) -> 0 | X48: =SUM(AK48,AX48,BK48,BX48,CK48) -> 0 | Y48: =SUM(AL48,AY48,BL48,BY48,CL48) -> 0 | Z48: =SUM(AM48,AZ48,BM48,BZ48,CM48) -> 0 | AA48: =SUM(AN48,BA48,BN48,CA48,CN48) -> 0 | ... AE48: =SUM(AR48,BE48,BR48,CE48,CR48) -> 0
A49: =A11 | B49: =B11 | C49: =C11 | E49: =E11 | F49: =F11 | T49: =SUM(AG49,AT49,BG49,BT49,CG49) -> 0 | U49: =SUM(AH49,AU49,BH49,BU49,CH49) -> 0 | V49: =SUM(AI49,AV49,BI49,BV49,CI49) -> 0 | W49: =SUM(AJ49,AW49,BJ49,BW49,CJ49) -> 0 | X49: =SUM(AK49,AX49,BK49,BX49,CK49) -> 0 | Y49: =SUM(AL49,AY49,BL49,BY49,CL49) -> 0 | Z49: =SUM(AM49,AZ49,BM49,BZ49,CM49) -> 0 | AA49: =SUM(AN49,BA49,BN49,CA49,CN49) -> 0 | ... AE49: =SUM(AR49,BE49,BR49,CE49,CR49) -> 0
A50: =A12 | B50: =B12 | C50: =C12 | E50: =E12 | F50: =F12 | T50: =SUM(AG50,AT50,BG50,BT50,CG50) -> 0 | U50: =SUM(AH50,AU50,BH50,BU50,CH50) -> 0 | V50: =SUM(AI50,AV50,BI50,BV50,CI50) -> 0 | W50: =SUM(AJ50,AW50,BJ50,BW50,CJ50) -> 0 | X50: =SUM(AK50,AX50,BK50,BX50,CK50) -> 0 | Y50: =SUM(AL50,AY50,BL50,BY50,CL50) -> 0 | Z50: =SUM(AM50,AZ50,BM50,BZ50,CM50) -> 0 | AA50: =SUM(AN50,BA50,BN50,CA50,CN50) -> 0 | ... AE50: =SUM(AR50,BE50,BR50,CE50,CR50) -> 0
A51: =A13 | B51: =B13 | C51: =C13 | E51: =E13 | F51: =F13 | T51: =SUM(AG51,AT51,BG51,BT51,CG51) -> 0 | U51: =SUM(AH51,AU51,BH51,BU51,CH51) -> 0 | V51: =SUM(AI51,AV51,BI51,BV51,CI51) -> 0 | W51: =SUM(AJ51,AW51,BJ51,BW51,CJ51) -> 0 | X51: =SUM(AK51,AX51,BK51,BX51,CK51) -> 0 | Y51: =SUM(AL51,AY51,BL51,BY51,CL51) -> 0 | Z51: =SUM(AM51,AZ51,BM51,BZ51,CM51) -> 0 | AA51: =SUM(AN51,BA51,BN51,CA51,CN51) -> 0 | ... AE51: =SUM(AR51,BE51,BR51,CE51,CR51) -> 0
A52: =A14 | B52: =B14 | C52: =C14 | E52: =E14 | F52: =F14 | T52: =SUM(AG52,AT52,BG52,BT52,CG52) -> 0 | U52: =SUM(AH52,AU52,BH52,BU52,CH52) -> 0 | V52: =SUM(AI52,AV52,BI52,BV52,CI52) -> 0 | W52: =SUM(AJ52,AW52,BJ52,BW52,CJ52) -> 0 | X52: =SUM(AK52,AX52,BK52,BX52,CK52) -> 0 | Y52: =SUM(AL52,AY52,BL52,BY52,CL52) -> 0 | Z52: =SUM(AM52,AZ52,BM52,BZ52,CM52) -> 0 | AA52: =SUM(AN52,BA52,BN52,CA52,CN52) -> 0 | ... AE52: =SUM(AR52,BE52,BR52,CE52,CR52) -> 0
A53: =A15 | B53: =B15 | C53: =C15 | E53: =E15 | F53: =F15 | T53: =SUM(AG53,AT53,BG53,BT53,CG53) -> 0 | U53: =SUM(AH53,AU53,BH53,BU53,CH53) -> 0 | V53: =SUM(AI53,AV53,BI53,BV53,CI53) -> 0 | W53: =SUM(AJ53,AW53,BJ53,BW53,CJ53) -> 0 | X53: =SUM(AK53,AX53,BK53,BX53,CK53) -> 0 | Y53: =SUM(AL53,AY53,BL53,BY53,CL53) -> 0 | Z53: =SUM(AM53,AZ53,BM53,BZ53,CM53) -> 0 | AA53: =SUM(AN53,BA53,BN53,CA53,CN53) -> 0 | ... AE53: =SUM(AR53,BE53,BR53,CE53,CR53) -> 0
... A71: =A33 | B71: =B33 | C71: =C33 | E71: =E33 | F71: =F33 | T71: =SUM(AG71,AT71,BG71,BT71,CG71) -> 0 | U71: =SUM(AH71,AU71,BH71,BU71,CH71) -> 0 | V71: =SUM(AI71,AV71,BI71,BV71,CI71) -> 0 | W71: =SUM(AJ71,AW71,BJ71,BW71,CJ71) -> 0 | X71: =SUM(AK71,AX71,BK71,BX71,CK71) -> 0 | Y71: =SUM(AL71,AY71,BL71,BY71,CL71) -> 0 | Z71: =SUM(AM71,AZ71,BM71,BZ71,CM71) -> 0 | AA71: =SUM(AN71,BA71,BN71,CA71,CN71) -> 0 | ... AE71: =SUM(AR71,BE71,BR71,CE71,CR71) -> 0
A78: # | B78: Vorname | C78: Nachname | E78: Beschäftigt auf Projekt seit | F78: Beschäftigt auf Projekt bis | G78: =G40+1 -> 1902 | T78: =G78 -> 1902 | AG78: =AG40+1 -> 1902 | AT78: =AT40+1 -> 1902 | BG78: =BG40+1 -> 1902 | BT78: =BT40+1 -> 1902 | CG78: =CG40+1 -> 1902
A79: # | G79: Jan | H79: Feb | I79: Mar | J79: Apr | K79: Mai | L79: Jun | M79: Jul | N79: Aug | O79: Sep | P79: Okt | Q79: Nov | R79: Dez | T79: Jan | U79: Feb | V79: Mar | W79: Apr | X79: Mai | Y79: Jun | Z79: Jul | AA79: Aug | AB79: Sep | AC79: Okt | AD79: Nov | AE79: Dez | AG79: Jan | AH79: Feb | AI79: Mar | AJ79: Apr | AK79: Mai | AL79: Jun | AM79: Jul | AN79: Aug | AO79: Sep | AP79: Okt | AQ79: Nov | AR79: Dez | AT79: Jan | AU79: Feb | AV79: Mar | AW79: Apr | AX79: Mai | AY79: Jun | AZ79: Jul | BA79: Aug | BB79: Sep | BC79: Okt | BD79: Nov | BE79: Dez | BG79: Jan | BH79: Feb | BI79: Mar | BJ79: Apr | BK79: Mai | BL79: Jun | BM79: Jul | BN79: Aug | BO79: Sep | BP79: Okt | BQ79: Nov | BR79: Dez | BT79: Jan | BU79: Feb | BV79: Mar | BW79: Apr | BX79: Mai | BY79: Jun | BZ79: Jul | CA79: Aug | CB79: Sep | CC79: Okt | CD79: Nov | CE79: Dez | CG79: Jan | CH79: Feb | CI79: Mar | CJ79: Apr | CK79: Mai | CL79: Jun | CM79: Jul | CN79: Aug | CO79: Sep | CP79: Okt | CQ79: Nov | CR79: Dez
A80: =A42 -> 1 | B80: =B42 | C80: =C42 | E80: =E42 | F80: =F42 | T80: =SUM(AG80,AT80,BG80,BT80,CG80) -> 0 | U80: =SUM(AH80,AU80,BH80,BU80,CH80) -> 0 | V80: =SUM(AI80,AV80,BI80,BV80,CI80) -> 0 | W80: =SUM(AJ80,AW80,BJ80,BW80,CJ80) -> 0 | X80: =SUM(AK80,AX80,BK80,BX80,CK80) -> 0 | Y80: =SUM(AL80,AY80,BL80,BY80,CL80) -> 0 | Z80: =SUM(AM80,AZ80,BM80,BZ80,CM80) -> 0 | AA80: =SUM(AN80,BA80,BN80,CA80,CN80) -> 0 | ... AE80: =SUM(AR80,BE80,BR80,CE80,CR80) -> 0
A81: =A43 | B81: =B43 | C81: =C43 | E81: =E43 | F81: =F43 | T81: =SUM(AG81,AT81,BG81,BT81,CG81) -> 0 | U81: =SUM(AH81,AU81,BH81,BU81,CH81) -> 0 | V81: =SUM(AI81,AV81,BI81,BV81,CI81) -> 0 | W81: =SUM(AJ81,AW81,BJ81,BW81,CJ81) -> 0 | X81: =SUM(AK81,AX81,BK81,BX81,CK81) -> 0 | Y81: =SUM(AL81,AY81,BL81,BY81,CL81) -> 0 | Z81: =SUM(AM81,AZ81,BM81,BZ81,CM81) -> 0 | AA81: =SUM(AN81,BA81,BN81,CA81,CN81) -> 0 | ... AE81: =SUM(AR81,BE81,BR81,CE81,CR81) -> 0
A82: =A44 | B82: =B44 | C82: =C44 | E82: =E44 | F82: =F44 | T82: =SUM(AG82,AT82,BG82,BT82,CG82) -> 0 | U82: =SUM(AH82,AU82,BH82,BU82,CH82) -> 0 | V82: =SUM(AI82,AV82,BI82,BV82,CI82) -> 0 | W82: =SUM(AJ82,AW82,BJ82,BW82,CJ82) -> 0 | X82: =SUM(AK82,AX82,BK82,BX82,CK82) -> 0 | Y82: =SUM(AL82,AY82,BL82,BY82,CL82) -> 0 | Z82: =SUM(AM82,AZ82,BM82,BZ82,CM82) -> 0 | AA82: =SUM(AN82,BA82,BN82,CA82,CN82) -> 0 | ... AE82: =SUM(AR82,BE82,BR82,CE82,CR82) -> 0
A83: =A45 | B83: =B45 | C83: =C45 | E83: =E45 | F83: =F45 | T83: =SUM(AG83,AT83,BG83,BT83,CG83) -> 0 | U83: =SUM(AH83,AU83,BH83,BU83,CH83) -> 0 | V83: =SUM(AI83,AV83,BI83,BV83,CI83) -> 0 | W83: =SUM(AJ83,AW83,BJ83,BW83,CJ83) -> 0 | X83: =SUM(AK83,AX83,BK83,BX83,CK83) -> 0 | Y83: =SUM(AL83,AY83,BL83,BY83,CL83) -> 0 | Z83: =SUM(AM83,AZ83,BM83,BZ83,CM83) -> 0 | AA83: =SUM(AN83,BA83,BN83,CA83,CN83) -> 0 | ... AE83: =SUM(AR83,BE83,BR83,CE83,CR83) -> 0
A84: =A46 | B84: =B46 | C84: =C46 | E84: =E46 | F84: =F46 | T84: =SUM(AG84,AT84,BG84,BT84,CG84) -> 0 | U84: =SUM(AH84,AU84,BH84,BU84,CH84) -> 0 | V84: =SUM(AI84,AV84,BI84,BV84,CI84) -> 0 | W84: =SUM(AJ84,AW84,BJ84,BW84,CJ84) -> 0 | X84: =SUM(AK84,AX84,BK84,BX84,CK84) -> 0 | Y84: =SUM(AL84,AY84,BL84,BY84,CL84) -> 0 | Z84: =SUM(AM84,AZ84,BM84,BZ84,CM84) -> 0 | AA84: =SUM(AN84,BA84,BN84,CA84,CN84) -> 0 | ... AE84: =SUM(AR84,BE84,BR84,CE84,CR84) -> 0
A85: =A47 | B85: =B47 | C85: =C47 | E85: =E47 | F85: =F47 | T85: =SUM(AG85,AT85,BG85,BT85,CG85) -> 0 | U85: =SUM(AH85,AU85,BH85,BU85,CH85) -> 0 | V85: =SUM(AI85,AV85,BI85,BV85,CI85) -> 0 | W85: =SUM(AJ85,AW85,BJ85,BW85,CJ85) -> 0 | X85: =SUM(AK85,AX85,BK85,BX85,CK85) -> 0 | Y85: =SUM(AL85,AY85,BL85,BY85,CL85) -> 0 | Z85: =SUM(AM85,AZ85,BM85,BZ85,CM85) -> 0 | AA85: =SUM(AN85,BA85,BN85,CA85,CN85) -> 0 | ... AE85: =SUM(AR85,BE85,BR85,CE85,CR85) -> 0
A86: =A48 | B86: =B48 | C86: =C48 | E86: =E48 | F86: =F48 | T86: =SUM(AG86,AT86,BG86,BT86,CG86) -> 0 | U86: =SUM(AH86,AU86,BH86,BU86,CH86) -> 0 | V86: =SUM(AI86,AV86,BI86,BV86,CI86) -> 0 | W86: =SUM(AJ86,AW86,BJ86,BW86,CJ86) -> 0 | X86: =SUM(AK86,AX86,BK86,BX86,CK86) -> 0 | Y86: =SUM(AL86,AY86,BL86,BY86,CL86) -> 0 | Z86: =SUM(AM86,AZ86,BM86,BZ86,CM86) -> 0 | AA86: =SUM(AN86,BA86,BN86,CA86,CN86) -> 0 | ... AE86: =SUM(AR86,BE86,BR86,CE86,CR86) -> 0
...
